Possible bug caused by unconditionally using 'utf-8' for `py bin` results
